<?xml version="1.0" encoding="utf-8"?>
<!-- This URDF was automatically created by SolidWorks to URDF Exporter! Originally created by Stephen Brawner (brawner@gmail.com) 
     Commit Version: 1.6.0-4-g7f85cfe  Build Version: 1.6.7995.38578
     For more information, please see http://wiki.ros.org/sw_urdf_exporter -->
<robot
  name="exfork_bot">
  <link
    name="base_footprint">
    <inertial>
      <origin
        xyz="0 0 0.015"
        rpy="0 0 0" />
      <mass
        value="9.42477796076939E-05" />
      <inertia
        ixx="7.09214541547898E-09"
        ixy="1.89326617253043E-28"
        ixz="-3.23117426778518E-27"
        iyy="7.09214541547898E-09"
        iyz="-2.58493941422821E-26"
        izz="4.71238898038469E-11" />
    </inertial>
    <visual>
      <origin
        xyz="0 0 0"
        rpy="0 0 0" />
      <geometry>
        <mesh
          filename="package://exfork_bot/meshes/base_footprint.STL" />
      </geometry>
      <material
        name="">
        <color
          rgba="0.792156862745098 0.819607843137255 0.933333333333333 1" />
      </material>
    </visual>
    <collision>
      <origin
        xyz="0 0 0"
        rpy="0 0 0" />
      <geometry>
        <mesh
          filename="package://exfork_bot/meshes/base_footprint.STL" />
      </geometry>
    </collision>
  </link>
  <link
    name="base_link">
    <inertial>
      <origin
        xyz="0.24419 -4.5799E-06 0.16554"
        rpy="0 0 0" />
      <mass
        value="28.317" />
      <inertia
        ixx="2.9156"
        ixy="0.0001163"
        ixz="-0.32989"
        iyy="2.612"
        iyz="3.0777E-05"
        izz="4.9812" />
    </inertial>
    <visual>
      <origin
        xyz="0 0 0"
        rpy="0 0 0" />
      <geometry>
        <mesh
          filename="package://exfork_bot/meshes/base_link.STL" />
      </geometry>
      <material
        name="">
        <color
          rgba="0.79216 0.81961 0.93333 1" />
      </material>
    </visual>
    <collision>
      <origin
        xyz="0 0 0"
        rpy="0 0 0" />
      <geometry>
        <mesh
          filename="package://exfork_bot/meshes/base_link.STL" />
      </geometry>
    </collision>
  </link>
  <joint
    name="base_joint"
    type="fixed">
    <origin
      xyz="-0.45174 0 0.04"
      rpy="0 0 0" />
    <parent
      link="base_footprint" />
    <child
      link="base_link" />
    <axis
      xyz="0 0 0" />
  </joint>
  <link
    name="l_wheel_link">
    <inertial>
      <origin
        xyz="1.5453E-08 -0.021167 1.6511E-08"
        rpy="0 0 0" />
      <mass
        value="1.2164" />
      <inertia
        ixx="0.0044416"
        ixy="-4.7872E-11"
        ixz="-4.9256E-07"
        iyy="0.0082257"
        iyz="-7.4615E-11"
        izz="0.0044446" />
    </inertial>
    <visual>
      <origin
        xyz="0 0 0"
        rpy="0 0 0" />
      <geometry>
        <mesh
          filename="package://exfork_bot/meshes/l_wheel_link.STL" />
      </geometry>
      <material
        name="">
        <color
          rgba="0.79216 0.81961 0.93333 1" />
      </material>
    </visual>
    <collision>
      <origin
        xyz="0 0 0"
        rpy="0 0 0" />
      <geometry>
        <mesh
          filename="package://exfork_bot/meshes/l_wheel_link.STL" />
      </geometry>
    </collision>
  </link>
  <joint
    name="l_wheel_joint"
    type="continuous">
    <origin
      xyz="0.46674 0.3245 0.06"
      rpy="0 0 0" />
    <parent
      link="base_link" />
    <child
      link="l_wheel_link" />
    <axis
      xyz="0 1 0" />
  </joint>
  <link
    name="r_wheel_link">
    <inertial>
      <origin
        xyz="9.6608E-09 0.021167 -2.0447E-08"
        rpy="0 0 0" />
      <mass
        value="1.2164" />
      <inertia
        ixx="0.0044421"
        ixy="5.3112E-11"
        ixz="1.2861E-06"
        iyy="0.0082257"
        iyz="-1.1243E-10"
        izz="0.004444" />
    </inertial>
    <visual>
      <origin
        xyz="0 0 0"
        rpy="0 0 0" />
      <geometry>
        <mesh
          filename="package://exfork_bot/meshes/r_wheel_link.STL" />
      </geometry>
      <material
        name="">
        <color
          rgba="0.79216 0.81961 0.93333 1" />
      </material>
    </visual>
    <collision>
      <origin
        xyz="0 0 0"
        rpy="0 0 0" />
      <geometry>
        <mesh
          filename="package://exfork_bot/meshes/r_wheel_link.STL" />
      </geometry>
    </collision>
  </link>
  <joint
    name="r_wheel_joint"
    type="continuous">
    <origin
      xyz="0.46674 -0.3245 0.06"
      rpy="0 0 0" />
    <parent
      link="base_link" />
    <child
      link="r_wheel_link" />
    <axis
      xyz="0 1 0" />
  </joint>
  <link
    name="laser_link">
    <inertial>
      <origin
        xyz="0 2.22044604925031E-16 -0.0394999999999999"
        rpy="0 0 0" />
      <mass
        value="0.39709731141375" />
      <inertia
        ixx="0.000365362617943268"
        ixy="0"
        ixz="1.21245706409418E-36"
        iyy="0.000365362617943268"
        iyz="-1.73102161812249E-35"
        izz="0.000317677849131001" />
    </inertial>
    <visual>
      <origin
        xyz="0 0 0"
        rpy="0 0 0" />
      <geometry>
        <mesh
          filename="package://exfork_bot/meshes/laser_link.STL" />
      </geometry>
      <material
        name="">
        <color
          rgba="0.792156862745098 0.819607843137255 0.933333333333333 1" />
      </material>
    </visual>
    <collision>
      <origin
        xyz="0 0 0"
        rpy="0 0 0" />
      <geometry>
        <mesh
          filename="package://exfork_bot/meshes/laser_link.STL" />
      </geometry>
    </collision>
  </link>
  <joint
    name="laser_joint"
    type="fixed">
    <origin
      xyz="0.45174 0 0.499"
      rpy="0 0 0" />
    <parent
      link="base_link" />
    <child
      link="laser_link" />
    <axis
      xyz="0 0 1" />
  </joint>
  <link
    name="casterarm_link">
    <inertial>
      <origin
        xyz="0.0760985533679645 -0.000230950841213717 -0.00827895192140704"
        rpy="0 0 0" />
      <mass
        value="1.79739905628811" />
      <inertia
        ixx="0.0388652941823"
        ixy="-3.74697430196857E-11"
        ixz="2.29003773192072E-05"
        iyy="0.00152979650498498"
        iyz="-1.08176244596861E-12"
        izz="0.0390330217726287" />
    </inertial>
    <visual>
      <origin
        xyz="0 0 0"
        rpy="0 0 0" />
      <geometry>
        <mesh
          filename="package://exfork_bot/meshes/casterarm_link.STL" />
      </geometry>
      <material
        name="">
        <color
          rgba="0.792156862745098 0.819607843137255 0.933333333333333 1" />
      </material>
    </visual>
    <collision>
      <origin
        xyz="0 0 0"
        rpy="0 0 0" />
      <geometry>
        <mesh
          filename="package://exfork_bot/meshes/casterarm_link.STL" />
      </geometry>
    </collision>
  </link>
  <joint
    name="casterarm_joint"
    type="continuous">
    <origin
      xyz="0.81205 0 0.1919"
      rpy="0 0 0" />
    <parent
      link="base_link" />
    <child
      link="casterarm_link" />
    <axis
      xyz="1 0 0" />
  </joint>
  <link
    name="caster1brkt_link">
    <inertial>
      <origin
        xyz="-0.00965828711006669 0.000371567422426722 -0.0440478994782961"
        rpy="0 0 0" />
      <mass
        value="0.182687039498993" />
      <inertia
        ixx="9.53962306279551E-05"
        ixy="1.05992172458199E-11"
        ixz="-1.40549307375338E-05"
        iyy="0.000101866845190863"
        iyz="6.82223367474751E-12"
        izz="0.000114704567301255" />
    </inertial>
    <visual>
      <origin
        xyz="0 0 0"
        rpy="0 0 0" />
      <geometry>
        <mesh
          filename="package://exfork_bot/meshes/caster1brkt_link.STL" />
      </geometry>
      <material
        name="">
        <color
          rgba="0.792156862745098 0.819607843137255 0.933333333333333 1" />
      </material>
    </visual>
    <collision>
      <origin
        xyz="0 0 0"
        rpy="0 0 0" />
      <geometry>
        <mesh
          filename="package://exfork_bot/meshes/caster1brkt_link.STL" />
      </geometry>
    </collision>
  </link>
  <joint
    name="caster1brkt_joint"
    type="continuous">
    <origin
      xyz="0.078 0.21133 -0.049249"
      rpy="0 0 0" />
    <parent
      link="casterarm_link" />
    <child
      link="caster1brkt_link" />
    <axis
      xyz="0 0 1" />
  </joint>
  <link
    name="caster1_link">
    <inertial>
      <origin
        xyz="-2.59431003513111E-07 -0.0249999395947416 1.65578340038941E-07"
        rpy="0 0 0" />
      <mass
        value="0.707028008737105" />
      <inertia
        ixx="0.0011142884489179"
        ixy="1.88390347320121E-10"
        ixz="-2.22191413272749E-09"
        iyy="0.00199724216026165"
        iyz="-6.35110944676939E-11"
        izz="0.00111428895047491" />
    </inertial>
    <visual>
      <origin
        xyz="0 0 0"
        rpy="0 0 0" />
      <geometry>
        <mesh
          filename="package://exfork_bot/meshes/caster1_link.STL" />
      </geometry>
      <material
        name="">
        <color
          rgba="0.792156862745098 0.819607843137255 0.933333333333333 1" />
      </material>
    </visual>
    <collision>
      <origin
        xyz="0 0 0"
        rpy="0 0 0" />
      <geometry>
        <mesh
          filename="package://exfork_bot/meshes/caster1_link.STL" />
      </geometry>
    </collision>
  </link>
  <joint
    name="caster1_joint"
    type="continuous">
    <origin
      xyz="-0.034301 0.025 -0.1064"
      rpy="0 0 0" />
    <parent
      link="caster1brkt_link" />
    <child
      link="caster1_link" />
    <axis
      xyz="0 0 1" />
  </joint>
  <link
    name="caster2brkt_link">
    <inertial>
      <origin
        xyz="-0.00965828710201835 0.000371567422425834 -0.0440478994782963"
        rpy="0 0 0" />
      <mass
        value="0.182687039498993" />
      <inertia
        ixx="9.53962306279549E-05"
        ixy="1.05992172375589E-11"
        ixz="-1.40549307375336E-05"
        iyy="0.000101866845190862"
        iyz="6.82223367162919E-12"
        izz="0.000114704567301255" />
    </inertial>
    <visual>
      <origin
        xyz="0 0 0"
        rpy="0 0 0" />
      <geometry>
        <mesh
          filename="package://exfork_bot/meshes/caster2brkt_link.STL" />
      </geometry>
      <material
        name="">
        <color
          rgba="0.792156862745098 0.819607843137255 0.933333333333333 1" />
      </material>
    </visual>
    <collision>
      <origin
        xyz="0 0 0"
        rpy="0 0 0" />
      <geometry>
        <mesh
          filename="package://exfork_bot/meshes/caster2brkt_link.STL" />
      </geometry>
    </collision>
  </link>
  <joint
    name="caster2brkt_joint"
    type="continuous">
    <origin
      xyz="0.078 -0.21533 -0.049249"
      rpy="0 0 0" />
    <parent
      link="casterarm_link" />
    <child
      link="caster2brkt_link" />
    <axis
      xyz="0 0 1" />
  </joint>
  <link
    name="caster2_link">
    <inertial>
      <origin
        xyz="-2.59431003513111E-07 -0.0249999395947416 1.65578340038941E-07"
        rpy="0 0 0" />
      <mass
        value="0.707028008737105" />
      <inertia
        ixx="0.0011142884489179"
        ixy="1.88390347278457E-10"
        ixz="-2.22191413278026E-09"
        iyy="0.00199724216026165"
        iyz="-6.35110944127552E-11"
        izz="0.00111428895047491" />
    </inertial>
    <visual>
      <origin
        xyz="0 0 0"
        rpy="0 0 0" />
      <geometry>
        <mesh
          filename="package://exfork_bot/meshes/caster2_link.STL" />
      </geometry>
      <material
        name="">
        <color
          rgba="0.792156862745098 0.819607843137255 0.933333333333333 1" />
      </material>
    </visual>
    <collision>
      <origin
        xyz="0 0 0"
        rpy="0 0 0" />
      <geometry>
        <mesh
          filename="package://exfork_bot/meshes/caster2_link.STL" />
      </geometry>
    </collision>
  </link>
  <joint
    name="caster2_joint"
    type="continuous">
    <origin
      xyz="-0.034301 0.025 -0.1064"
      rpy="0 0 0" />
    <parent
      link="caster2brkt_link" />
    <child
      link="caster2_link" />
    <axis
      xyz="0 0 1" />
  </joint>
  <link
    name="caster3brkt_link">
    <inertial>
      <origin
        xyz="-0.0096583 0.00037157 -0.044048"
        rpy="0 0 0" />
      <mass
        value="0.18269" />
      <inertia
        ixx="9.5396E-05"
        ixy="1.0599E-11"
        ixz="-1.4055E-05"
        iyy="0.00010187"
        iyz="6.8222E-12"
        izz="0.0001147" />
    </inertial>
    <visual>
      <origin
        xyz="0 0 0"
        rpy="0 0 0" />
      <geometry>
        <mesh
          filename="package://exfork_bot/meshes/caster3brkt_link.STL" />
      </geometry>
      <material
        name="">
        <color
          rgba="0.79216 0.81961 0.93333 1" />
      </material>
    </visual>
    <collision>
      <origin
        xyz="0 0 0"
        rpy="0 0 0" />
      <geometry>
        <mesh
          filename="package://exfork_bot/meshes/caster3brkt_link.STL" />
      </geometry>
    </collision>
  </link>
  <joint
    name="caster3brkt_joint"
    type="continuous">
    <origin
      xyz="-0.27695 0.62704 0.14265"
      rpy="0 0 0" />
    <parent
      link="base_link" />
    <child
      link="caster3brkt_link" />
    <axis
      xyz="0 0 1" />
  </joint>
  <link
    name="caster3_link">
    <inertial>
      <origin
        xyz="-2.5943E-07 -0.025 1.6558E-07"
        rpy="0 0 0" />
      <mass
        value="0.70703" />
      <inertia
        ixx="0.0011143"
        ixy="1.8839E-10"
        ixz="-2.2219E-09"
        iyy="0.0019972"
        iyz="-6.3511E-11"
        izz="0.0011143" />
    </inertial>
    <visual>
      <origin
        xyz="0 0 0"
        rpy="0 0 0" />
      <geometry>
        <mesh
          filename="package://exfork_bot/meshes/caster3_link.STL" />
      </geometry>
      <material
        name="">
        <color
          rgba="0.79216 0.81961 0.93333 1" />
      </material>
    </visual>
    <collision>
      <origin
        xyz="0 0 0"
        rpy="0 0 0" />
      <geometry>
        <mesh
          filename="package://exfork_bot/meshes/caster3_link.STL" />
      </geometry>
    </collision>
  </link>
  <joint
    name="caster3_joint"
    type="continuous">
    <origin
      xyz="-0.034301 0.025 -0.1064"
      rpy="0 0 0" />
    <parent
      link="caster3brkt_link" />
    <child
      link="caster3_link" />
    <axis
      xyz="0 0 1" />
  </joint>
  <link
    name="caster4brkt_link">
    <inertial>
      <origin
        xyz="-0.0096583 0.00037157 -0.044048"
        rpy="0 0 0" />
      <mass
        value="0.18269" />
      <inertia
        ixx="9.5396E-05"
        ixy="1.0599E-11"
        ixz="-1.4055E-05"
        iyy="0.00010187"
        iyz="6.8222E-12"
        izz="0.0001147" />
    </inertial>
    <visual>
      <origin
        xyz="0 0 0"
        rpy="0 0 0" />
      <geometry>
        <mesh
          filename="package://exfork_bot/meshes/caster4brkt_link.STL" />
      </geometry>
      <material
        name="">
        <color
          rgba="0.79216 0.81961 0.93333 1" />
      </material>
    </visual>
    <collision>
      <origin
        xyz="0 0 0"
        rpy="0 0 0" />
      <geometry>
        <mesh
          filename="package://exfork_bot/meshes/caster4brkt_link.STL" />
      </geometry>
    </collision>
  </link>
  <joint
    name="caster4brkt_joint"
    type="continuous">
    <origin
      xyz="-0.27695 -0.63104 0.14265"
      rpy="0 0 0" />
    <parent
      link="base_link" />
    <child
      link="caster4brkt_link" />
    <axis
      xyz="0 0 1" />
  </joint>
  <link
    name="caster4_link">
    <inertial>
      <origin
        xyz="-2.5943E-07 0.025 1.6558E-07"
        rpy="0 0 0" />
      <mass
        value="0.70703" />
      <inertia
        ixx="0.0011143"
        ixy="1.8839E-10"
        ixz="-2.2219E-09"
        iyy="0.0019972"
        iyz="-6.3511E-11"
        izz="0.0011143" />
    </inertial>
    <visual>
      <origin
        xyz="0 0 0"
        rpy="0 0 0" />
      <geometry>
        <mesh
          filename="package://exfork_bot/meshes/caster4_link.STL" />
      </geometry>
      <material
        name="">
        <color
          rgba="0.79216 0.81961 0.93333 1" />
      </material>
    </visual>
    <collision>
      <origin
        xyz="0 0 0"
        rpy="0 0 0" />
      <geometry>
        <mesh
          filename="package://exfork_bot/meshes/caster4_link.STL" />
      </geometry>
    </collision>
  </link>
  <joint
    name="caster4_joint"
    type="continuous">
    <origin
      xyz="-0.034301 -0.025 -0.1064"
      rpy="0 0 0" />
    <parent
      link="caster4brkt_link" />
    <child
      link="caster4_link" />
    <axis
      xyz="0 0 1" />
  </joint>
  <link
    name="load_link">
    <inertial>
      <origin
        xyz="0 0 0.5"
        rpy="0 0 0" />
      <mass
        value="1000" />
      <inertia
        ixx="166.67"
        ixy="0"
        ixz="0"
        iyy="166.67"
        iyz="0"
        izz="166.67" />
    </inertial>
    <visual>
      <origin
        xyz="0 0 0"
        rpy="0 0 0" />
      <geometry>
        <mesh
          filename="package://exfork_bot/meshes/load_link.STL" />
      </geometry>
      <material
        name="">
        <color
          rgba="0.79216 0.81961 0.93333 1" />
      </material>
    </visual>
    <collision>
      <origin
        xyz="0 0 0"
        rpy="0 0 0" />
      <geometry>
        <mesh
          filename="package://exfork_bot/meshes/load_link.STL" />
      </geometry>
    </collision>
  </link>
  <joint
    name="load_joint"
    type="fixed">
    <origin
      xyz="-0.29248 -0.0010935 0.05"
      rpy="0 0 0" />
    <parent
      link="base_link" />
    <child
      link="load_link" />
    <axis
      xyz="0 1 0" />
  </joint>
</robot>